Workbook
Name 矮人之坚毅: 图表!$B$278
Name 俺寻思能行: 图表!$B$182
Name 暗行者: 图表!$B$164
Name 奥法骑士: 图表!$B$197
Name 暴风龙纹: 图表!$B$293
Name 本命武器: 图表!$B$195
Name 冰封诅咒: 图表!$B$244
Name 不死生物: 图表!$I$2:$I$6
Name 拆迁法术: 图表!$B$266
Name 抄录龙纹: 图表!$B$302
Name 超自然直觉: 图表!$B$80
Name 炽烈爆发: 图表!$B$246
Name 出神入化: 图表!$B$202
Name 畜牧龙纹: 图表!$B$298
Name 穿刺者: 图表!$B$68
Name 穿透与回旋: 图表!$B$110
Name 创生圣言: 图表!$B$47
Name 创造龙纹: 图表!$B$299
Name 大厨: 图表!$B$130
Name 大一统理论: 图表!$B$147
Name 德鲁伊: 图表!$K$24:$K$33
Name 低身之机敏: 图表!$B$284
Name 第二领域: 图表!$B$157
Name 点穴: 图表!$B$186
Name 动作如潮: 图表!$B$103
Name 斗殴高手: 图表!$B$132
Name 毒师: 图表!$B$165
Name 对人立体机动装置: 图表!$B$106
Name 钝击者: 图表!$B$70
Name 盾牌大师: 图表!$B$129
Name 多样眼波射线: 图表!$B$274
Name 额外吟唱: 图表!$B$161
Name 二刀流: 图表!$B$86
Name 法师: 图表!$M$24:$M$36
Name 法术储存: 图表!$B$250
Name 法术穿透: 图表!$B$177
Name 法术对抗大师: 图表!$B$62
Name 法术分裂: 图表!$B$226
Name 法术恒久: 图表!$B$267
Name 法术极效: 图表!$B$227
Name 法术疾发: 图表!$B$234
Name 法术跨域: 图表!$B$253
Name 法术扩展: 图表!$B$237
Name 法术强效: 图表!$B$228
Name 法术射手: 图表!$B$64
Name 法术瞬发: 图表!$B$232
Name 法术速发: 图表!$B$233
Name 法术塑形: 图表!$B$236
Name 法术稳固: 图表!$B$230
Name 法术延时: 图表!$B$229
Name 法术余力: 图表!$B$225
Name 法术专攻: 图表!$B$223
Name 法术追踪: 图表!$B$231
Name 奋力冲刺: 图表!$B$52
Name 风浪射手: 图表!$B$118
Name 封锁记忆: 图表!$B$257
Name 否决神力: 图表!$B$290
Name 弗莱格索斯之焰: 图表!$B$281
Name 浮光掠影: 图表!$B$107
Name 钢铁坐骑: 图表!$B$169

Sheet 角色
A1: 角色
A2: 浅绿色方格，为公式自动计算。浅蓝色方格，为下拉框式选择。白色方格，必须自行填写。灰色方格，可以自行修改其中的描述名称，也可以不改。
B3: 角色名 | R3: 背景
B4: 玩家名 | R4: 阵营
R5: 信仰
B6: 生物类型 | J6: 体型 | R6: 特点
B7: 种族 | J7: 性别 | R7: 理想
B8: 亚种 | J8: 年龄 | R8: 牵绊
R9: 缺点
B10: 角色外貌描述 | R10: 技能熟练项
R11: 语言
R12: 故事
B15: 角色形象图片

Sheet 主要情况
A1: 主要情况
A2: 浅绿色方格，为公式自动计算。浅蓝色方格，为下拉框式选择。白色方格，必须自行填写。灰色方格，可以自行修改其中的描述名称，也可以不改。
A3: 属性 | J3: 职业 | AD3: 种族 | AZ3: 资源消耗记录
D4: 属性值 | E4: 调整值 | F4: 豁免熟练 | G4: 豁免修正 | H4: 豁免总值 | J4: 总等级 | M4: =SUM(W7:Z10) -> 0 | R4: 熟练 加值 | V4: =MAX(INT((M4+7)/4)+Y5,2) -> 2 | Y4: 修正 | AD4: 特性 | AH4: 效果 | AZ4: 名称 | BC4: 当前值 | BF4: 最大值 | BI4: 恢复
A5: 力量 | E5: =INT(D5/2-5) -> -5 | F5: 无 | H5: =E5+G5+IF(F5="有",V4,0) -> -5 | AD5: 生物类型 | BE5: /
J6: 职业与兼职 | R6: 子职业 | W6: 等级 | AD6: 属性值提升 | BE6: /
A7: 敏捷 | E7: =INT(D7/2-5) -> -5 | F7: 无 | H7: =E7+G7+IF(F7="有",V4,0) -> -5 | J7: 初始职业 | AD7: 体型 | BE7: /
J8: 兼职一 | BE8: /
A9: 体质 | E9: =INT(D9/2-5) -> -5 | F9: 无 | H9: =E9+G9+IF(F9="有",V4,0) -> -5 | J9: 兼职二 | BE9: /
J10: 兼职三 | BE10: /
A11: 智力 | E11: =INT(D11/2-5) -> -5 | F11: 无 | H11: =E11+G11+IF(F11="有",V4,0) -> -5 | M11: 当前值 | R11: 最大值 | V11: 生命上限修正 | BE11: /
J12: 生命值 | Q12: / | R12: =图表!B21+V12 -> 0 | BE12: /
A13: 感知 | E13: =INT(D13/2-5) -> -5 | F13: 无 | H13: =E13+G13+IF(F13="有",V4,0) -> -5 | V13: 临时生命值 | BE13: /
J14: 生命骰数量 | M14: 1 | Q14: / | R14: =M4 -> 0 | AD14: 语言 | BE14: /
A16: 技能 | H16: 战斗数据 | AD16: 专长 | AZ16: 状态记录
A17: 力量系 | D17: 技能熟练 | E17: 技能修正 | F17: 技能总值 | I17: 先攻熟练 | M17: 先攻修正 | Q17: 先攻总值 | AD17: 等级 | AF17: 名称 | AJ17: 效果 | AU17: 可选项说明 | AZ17: 在此记录你具有的增益效果、不利影响。
A18: 运动 | D18: 无 | F18: =E5+E18+IF(D18="熟练",V4,0)+IF(D18="专精",V4*2,0)+IF(D18="万事通",INT(V4/2),0) -> -5 | H18: 先攻 | I18: 无 | Q18: =E7+M18+IF(I18="熟练",V4,0)+IF(I18="万事通",INT(V4/2),0) -> -5 | AD18: 1
A19: 威吓 | D19: 无 | F19: =E5+E19+IF(D19="熟练",V4,0)+IF(D19="专精",V4*2,0)+IF(D19="万事通",INT(V4/2),0) -> -5 | H19: 防具 | I19: 防具类型 | M19: 装备加值 | Q19: AC值 | V19: 其它修正 | Y19: AC总值 | AD19: 1
A20: 敏捷系 | D20: 技能熟练 | E20: 技能修正 | F20: 技能总值 | H20: 盔甲 | M20: 0 | Q20: =M20+V4+IF(I20="无盔甲",8+E7,0)+IF(I20="镶钉皮甲",10+E7)+IF(I20="半身板甲",13+MIN(E7,2),0)+IF(I20="板甲",16,0)+IF(I20="法师护甲",11+E7,0)+IF(AND(I20="武僧无甲防御",I21="无盾牌"),8+E7+E13,0)+IF(I20="狂战士无甲防御",8+E7+E9,0) -> 2 | Y20: =Q20+Q21+V20 -> 2 | AD20: 3
A21: 体操 | D21: 无 | F21: =E7+E21+IF(D21="熟练",V4,0)+IF(D21="专精",V4*2,0)+IF(D21="万事通",INT(V4/2),0) -> -5 | H21: 盾牌 | Q21: =(M21*IF(I21="有盾牌",1,0)+IF(I21="有盾牌",2,0)) -> 0 | AD21: 6
A22: 巧手 | D22: 无 | F22: =E7+E22+IF(D22="熟练",V4,0)+IF(D22="专精",V4*2,0)+IF(D22="万事通",INT(V4/2),0) -> -5 | H22: 攻击 | I22: 攻击类型 | M22: 装备加值 | Q22: 关联属性 | V22: 其它修正 | Y22: 命中总值 | AD22: 9
A23: 隐匿 | D23: 无 | F23: =E7+E23+IF(D23="熟练",V4,0)+IF(D23="专精",V4*2,0)+IF(D23="万事通",INT(V4/2),0) -> -5 | H23: 主武器 | M23: 0 | Q23: 力量 | Y23: =V4+M23+V23+IF(Q23="力量",E5,0)+IF(Q23="敏捷",E7,0)+IF(Q23="体质",E9,0)+IF(Q23="智力",E11,0)+IF(Q23="感知",E13,0) -> -3 | AD23: 12
A24: 智力系 | D24: 技能熟练 | E24: 技能修正 | F24: 技能总值 | H24: 副武器 | M24: 0 | Q24: 敏捷 | Y24: =V4+M24+V24+IF(Q24="力量",E5,0)+IF(Q24="敏捷",E7,0)+IF(Q24="体质",E9,0)+IF(Q24="智力",E11,0)+IF(Q24="感知",E13,0) -> -3 | AD24: 15
A25: 奥秘 | D25: 无 | F25: =E11+E25+IF(D25="熟练",V4,0)+IF(D25="专精",V4*2,0)+IF(D25="万事通",INT(V4/2),0) -> -5 | H25: 法术攻击 | M25: 0 | Q25: 感知 | Y25: =V4+M25+V25+IF(Q25="力量",E5,0)+IF(Q25="敏捷",E7,0)+IF(Q25="体质",E9,0)+IF(Q25="智力",E11,0)+IF(Q25="感知",E13,0) -> -3 | AD25: 18
A26: 灵能 | D26: 无 | F26: =E11+E26+IF(D26="熟练",V4,0)+IF(D26="专精",V4*2,0)+IF(D26="万事通",INT(V4/2),0) -> -5 | H26: 豁免 | I26: 豁免来源 | M26: 装备加值 | Q26: 关联属性 | V26: 其它修正 | Y26: 豁免DC
A27: 宗教 | D27: 无 | F27: =E11+E27+IF(D27="熟练",V4,0)+IF(D27="专精",V4*2,0)+IF(D27="万事通",INT(V4/2),0) -> -5 | H27: 法术 | M27: 0 | Q27: 感知 | Y27: =8+V4+M27+V27+IF(Q27="力量",E5,0)+IF(Q27="敏捷",E7,0)+IF(Q27="体质",E9,0)+IF(Q27="智力",E11,0)+IF(Q27="感知",E13,0) -> 5
A28: 历史 | D28: 无 | F28: =E11+E28+IF(D28="熟练",V4,0)+IF(D28="专精",V4*2,0)+IF(D28="万事通",INT(V4/2),0) -> -5 | H28: 非法术 | M28: 0 | Q28: 力量 | Y28: =8+V4+M28+V28+IF(Q28="力量",E5,0)+IF(Q28="敏捷",E7,0)+IF(Q28="体质",E9,0)+IF(Q28="智力",E11,0)+IF(Q28="感知",E13,0) -> 5
A29: 自然 | D29: 无 | F29: =E11+E29+IF(D29="熟练",V4,0)+IF(D29="专精",V4*2,0)+IF(D29="万事通",INT(V4/2),0) -> -5 | H29: 速度 | I29: 种族基本速度 | M29: 力量加成 | Q29: 其它修正 | V29: 最终速度 | AD29: 装备熟练项
A30: 调查 | D30: 无 | F30: =E11+E30+IF(D30="熟练",V4,0)+IF(D30="专精",V4*2,0)+IF(D30="万事通",INT(V4/2),0) -> -5 | H30: 步行速度 | I30: 30 | M30: =5*E5 -> -25 | V30: =SUM(I30:U30) -> 5 | Y30: 尺 | AD30: 非异种武器 | AH30: 简易武器
A31: 表演 | D31: 无 | F31: =E11+E31+IF(D31="熟练",V4,0)+IF(D31="专精",V4*2,0)+IF(D31="万事通",INT(V4/2),0) -> -5 | H31: 其它速度 | I31: 飞行，游泳，攀爬，掘地 | Y31: 尺 | AD31: 异种武器 | AH31: 无
A32: 感知系 | D32: 技能熟练 | E32: 技能修正 | F32: 技能总值 | H32: 伤害抵抗 | AD32: 防具 | AH32: 无
A33: 察觉 | D33: 无 | F33: =E13+E33+IF(D33="熟练",V4,0)+IF(D33="专精",V4*2,0)+IF(D33="万事通",INT(V4/2),0) -> -5 | H33: 伤害抗性 | AD33: 配件 | AH33: 无
A34: 洞悉 | D34: 无 | F34: =E13+E34+IF(D34="熟练",V4,0)+IF(D34="专精",V4*2,0)+IF(D34="万事通",INT(V4/2),0) -> -5 | H34: 伤害免疫
A35: 医药 | D35: 无 | F35: =E13+E35+IF(D35="熟练",V4,0)+IF(D35="专精",V4*2,0)+IF(D35="万事通",INT(V4/2),0) -> -5 | H35: 伤害吸收 | AD35: 常用掷骰指令
A36: 生存 | D36: 无 | F36: =E13+E36+IF(D36="熟练",V4,0)+IF(D36="专精",V4*2,0)+IF(D36="万事通",INT(V4/2),0) -> -5 | H36: 伤害易伤 | AD36: 巨剑伤害
A37: 驯兽 | D37: 无 | F37: =E13+E37+IF(D37="熟练",V4,0)+IF(D37="专精",V4*2,0)+IF(D37="万事通",INT(V4/2),0) -> -5 | H37: 状态抵抗 | AD37: 先攻
A38: 游说 | D38: 无 | F38: =E13+E38+IF(D38="熟练",V4,0)+IF(D38="专精",V4*2,0)+IF(D38="万事通",INT(V4/2),0) -> -5 | H38: 豁免优势 | AD38: 火球术
A39: 欺瞒 | D39: 无 | F39: =E13+E39+IF(D39="熟练",V4,0)+IF(D39="专精",V4*2,0)+IF(D39="万事通",INT(V4/2),0) -> -5 | H39: 状态免疫 | AD39: 专注豁免

Sheet 职业特性
A1: 职业特性
I2: 初始职业 | L2: =主要情况!M7 -> 0 | AJ2: 子职业 | AM2: =主要情况!R7 -> 0
A3: 等级 | C3: 特性 | AA3: 等级 | AC3: 特性
A4: 1 | AA4: 1
A5: 2
A6: 3
A7: 4
A8: 5
A9: 6
A10: 7
A11: 8
A12: 9 | AJ12: 职业特色选项 | AM12: 魔能祈唤
A13: 10 | AA13: 等级 | AC13: 特性
A14: 11
A15: 12
A16: 13
A17: 14
A18: 15
A19: 16
A20: 17
A21: 18
A22: 19
A23: 20
I28: 兼职一 | L28: =主要情况!M8 -> 0 | AJ28: 子职业 | AM28: =主要情况!R8 -> 0
A29: 等级 | C29: 特性 | AA29: 等级 | AC29: 特性
A30: 1 | AA30: 1
A31: 2
A32: 3
A33: 4
A34: 5
A35: 6
A36: 7
A37: 8
A38: 9 | AJ38: 职业特色选项 | AM38: 制造物品
A39: 10 | AA39: 等级 | AC39: 特性
A40: 11
A41: 12
A42: 13
A43: 14
A44: 15
...

Sheet 装备
A1: 装备
A3: 非魔法物品 | AC3: 魔法物品
A4: 名称 | E4: 特殊 | G4: 描述 | S4: 单价 | X4: 数量 | AC4: 名称 | AG4: 同调 | AI4: 描述 | AW4: 单价 | BB4: 数量
S5: =IF($A5<>0,IF($E5<>0,VLOOKUP($E5,图表!$A$306:$C$317,3,0)+VLOOKUP($A5,图表!$A$330:$C$475,3,0),VLOOKUP($A5,图表!$A$330:$C$475,3,0)),"") | V5: gp× | AG5: =IF($AC5<>0,VLOOKUP($AC5,图表!$E$330:$H$1139,2,0),"") | AW5: =IF($AC5<>0,VLOOKUP($AC5,图表!$E$330:$H$1139,4,0),"") | AZ5: gp× | CB5: =IF(S5<>"",S5*X5,"") | CC5: =IF(AW5<>"",AW5*BB5,"")
S6: =IF($A6<>0,IF($E6<>0,VLOOKUP($E6,图表!$A$306:$C$317,3,0)+VLOOKUP($A6,图表!$A$330:$C$475,3,0),VLOOKUP($A6,图表!$A$330:$C$475,3,0)),"") | V6: gp× | AG6: =IF($AC6<>0,VLOOKUP($AC6,图表!$E$330:$H$1139,2,0),"") | AW6: =IF($AC6<>0,VLOOKUP($AC6,图表!$E$330:$H$1139,4,0),"") | AZ6: gp× | CB6: =IF(S6<>"",S6*X6,"") | CC6: =IF(AW6<>"",AW6*BB6,"")
S7: =IF($A7<>0,IF($E7<>0,VLOOKUP($E7,图表!$A$306:$C$317,3,0)+VLOOKUP($A7,图表!$A$330:$C$475,3,0),VLOOKUP($A7,图表!$A$330:$C$475,3,0)),"") | V7: gp× | AG7: =IF($AC7<>0,VLOOKUP($AC7,图表!$E$330:$H$1139,2,0),"") | AW7: =IF($AC7<>0,VLOOKUP($AC7,图表!$E$330:$H$1139,4,0),"") | AZ7: gp× | CB7: =IF(S7<>"",S7*X7,"") | CC7: =IF(AW7<>"",AW7*BB7,"")
S8: =IF($A8<>0,IF($E8<>0,VLOOKUP($E8,图表!$A$306:$C$317,3,0)+VLOOKUP($A8,图表!$A$330:$C$475,3,0),VLOOKUP($A8,图表!$A$330:$C$475,3,0)),"") | V8: gp× | AG8: =IF($AC8<>0,VLOOKUP($AC8,图表!$E$330:$H$1139,2,0),"") | AW8: =IF($AC8<>0,VLOOKUP($AC8,图表!$E$330:$H$1139,4,0),"") | AZ8: gp× | CB8: =IF(S8<>"",S8*X8,"") | CC8: =IF(AW8<>"",AW8*BB8,"")
S9: =IF($A9<>0,IF($E9<>0,VLOOKUP($E9,图表!$A$306:$C$317,3,0)+VLOOKUP($A9,图表!$A$330:$C$475,3,0),VLOOKUP($A9,图表!$A$330:$C$475,3,0)),"") | V9: gp× | AG9: =IF($AC9<>0,VLOOKUP($AC9,图表!$E$330:$H$1139,2,0),"") | AW9: =IF($AC9<>0,VLOOKUP($AC9,图表!$E$330:$H$1139,4,0),"") | AZ9: gp× | CB9: =IF(S9<>"",S9*X9,"") | CC9: =IF(AW9<>"",AW9*BB9,"")
S10: =IF($A10<>0,IF($E10<>0,VLOOKUP($E10,图表!$A$306:$C$317,3,0)+VLOOKUP($A10,图表!$A$330:$C$475,3,0),VLOOKUP($A10,图表!$A$330:$C$475,3,0)),"") | V10: gp× | AG10: =IF($AC10<>0,VLOOKUP($AC10,图表!$E$330:$H$1139,2,0),"") | AW10: =IF($AC10<>0,VLOOKUP($AC10,图表!$E$330:$H$1139,4,0),"") | AZ10: gp× | CB10: =IF(S10<>"",S10*X10,"") | CC10: =IF(AW10<>"",AW10*BB10,"")
S11: =IF($A11<>0,IF($E11<>0,VLOOKUP($E11,图表!$A$306:$C$317,3,0)+VLOOKUP($A11,图表!$A$330:$C$475,3,0),VLOOKUP($A11,图表!$A$330:$C$475,3,0)),"") | V11: gp× | AG11: =IF($AC11<>0,VLOOKUP($AC11,图表!$E$330:$H$1139,2,0),"") | AW11: =IF($AC11<>0,VLOOKUP($AC11,图表!$E$330:$H$1139,4,0),"") | AZ11: gp× | CB11: =IF(S11<>"",S11*X11,"") | CC11: =IF(AW11<>"",AW11*BB11,"")
S12: =IF($A12<>0,IF($E12<>0,VLOOKUP($E12,图表!$A$306:$C$317,3,0)+VLOOKUP($A12,图表!$A$330:$C$475,3,0),VLOOKUP($A12,图表!$A$330:$C$475,3,0)),"") | V12: gp× | AG12: =IF($AC12<>0,VLOOKUP($AC12,图表!$E$330:$H$1139,2,0),"") | AW12: =IF($AC12<>0,VLOOKUP($AC12,图表!$E$330:$H$1139,4,0),"") | AZ12: gp× | CB12: =IF(S12<>"",S12*X12,"") | CC12: =IF(AW12<>"",AW12*BB12,"")
S13: =IF($A13<>0,IF($E13<>0,VLOOKUP($E13,图表!$A$306:$C$317,3,0)+VLOOKUP($A13,图表!$A$330:$C$475,3,0),VLOOKUP($A13,图表!$A$330:$C$475,3,0)),"") | V13: gp× | AG13: =IF($AC13<>0,VLOOKUP($AC13,图表!$E$330:$H$1139,2,0),"") | AW13: =IF($AC13<>0,VLOOKUP($AC13,图表!$E$330:$H$1139,4,0),"") | AZ13: gp× | CB13: =IF(S13<>"",S13*X13,"") | CC13: =IF(AW13<>"",AW13*BB13,"")
S14: =IF($A14<>0,IF($E14<>0,VLOOKUP($E14,图表!$A$306:$C$317,3,0)+VLOOKUP($A14,图表!$A$330:$C$475,3,0),VLOOKUP($A14,图表!$A$330:$C$475,3,0)),"") | V14: gp× | AG14: =IF($AC14<>0,VLOOKUP($AC14,图表!$E$330:$H$1139,2,0),"") | AW14: =IF($AC14<>0,VLOOKUP($AC14,图表!$E$330:$H$1139,4,0),"") | AZ14: gp× | CB14: =IF(S14<>"",S14*X14,"") | CC14: =IF(AW14<>"",AW14*BB14,"")
S15: =IF($A15<>0,IF($E15<>0,VLOOKUP($E15,图表!$A$306:$C$317,3,0)+VLOOKUP($A15,图表!$A$330:$C$475,3,0),VLOOKUP($A15,图表!$A$330:$C$475,3,0)),"") | V15: gp× | AG15: =IF($AC15<>0,VLOOKUP($AC15,图表!$E$330:$H$1139,2,0),"") | AW15: =IF($AC15<>0,VLOOKUP($AC15,图表!$E$330:$H$1139,4,0),"") | AZ15: gp× | CB15: =IF(S15<>"",S15*X15,"") | CC15: =IF(AW15<>"",AW15*BB15,"")
S16: =IF($A16<>0,IF($E16<>0,VLOOKUP($E16,图表!$A$306:$C$317,3,0)+VLOOKUP($A16,图表!$A$330:$C$475,3,0),VLOOKUP($A16,图表!$A$330:$C$475,3,0)),"") | V16: gp× | AG16: =IF($AC16<>0,VLOOKUP($AC16,图表!$E$330:$H$1139,2,0),"") | AW16: =IF($AC16<>0,VLOOKUP($AC16,图表!$E$330:$H$1139,4,0),"") | AZ16: gp× | CB16: =IF(S16<>"",S16*X16,"") | CC16: =IF(AW16<>"",AW16*BB16,"")
... S25: =IF($A25<>0,IF($E25<>0,VLOOKUP($E25,图表!$A$306:$C$317,3,0)+VLOOKUP($A25,图表!$A$330:$C$475,3,0),VLOOKUP($A25,图表!$A$330:$C$475,3,0)),"") | V25: gp× | AG25: =IF($AC25<>0,VLOOKUP($AC25,图表!$E$330:$H$1139,2,0),"") | AW25: =IF($AC25<>0,VLOOKUP($AC25,图表!$E$330:$H$1139,4,0),"") | AZ25: gp× | CB25: =IF(S25<>"",S25*X25,"") | CC25: =IF(AW25<>"",AW25*BB25,"")
A26: 负重 | AC26: 购物
A27: 有力体型 | G27: 无有力体型 | AC27: 魔法物品总开销 | AI27: =SUM(CC5:CC25) -> 0 | AS27: gp
A28: 负重能力 | G28: =图表!T73 -> #N/A | Q28: 磅 | AC28: 非魔法物品总开销 | AI28: =SUM(CB5:CB25) -> 0 | AS28: gp | AV28: 同调总数 | AZ28: =COUNTIF(AG5:AH25,"是") -> 0 | BB28: 件
A29: 装备总重 | Q29: 磅 | AC29: 初始资金 | AI29: 999999 | AS29: gp
A30: 是否超载 | G30: =IF(G29>G28,"超载","未超载") -> #N/A | AC30: 剩余资金 | AI30: =AI29-AI27-AI28 -> 999999 | AS30: gp

Sheet 法术
A1: 法术
A2: 关联属性 | E2: =主要情况!Q27 -> 感知 | I2: 法术豁免DC | N2: =主要情况!Y27 -> 5 | R2: 可用环法数量 | W2: 准备法术 | AD2: 个 | AF2: 施法者等级 | AJ2: 14 | AL2: 级 | AN2: 环阶 | AP2: 施法者法术位 | AV2: 环阶 | AX2: 契约魔法
A3: 法术类型 | E3: =主要情况!I27 -> 0 | I3: 法术攻击加值 | N3: =主要情况!Y25 -> -3 | R3: 已知戏法 | Z3: 个 | AF3: 契术师等级 | AJ3: 15 | AL3: 级 | AN3: 0 | AP3: ∞ | AV3: 0 | AX3: ∞
A4: 法术 | E4: 环阶 | G4: 法术详述 | AL4: 来源 | AN4: 1 | AP4: 0 | AR4: / | AS4: =IF(AJ2>5,6,IF(AJ2>3,5,IF(AJ2>1,4,IF(AJ2>0,3,0)))) -> 6 | AV4: 1 | AX4: 0 | AZ4: / | BA4: =IF(AJ3=2,2,IF(AJ3=1,1,0)) -> 0
AN5: 2 | AP5: 0 | AR5: / | AS5: =IF(AJ2>15,6,IF(AJ2>11,5,IF(AJ2>7,4,IF(AJ2>3,3,IF(AJ2>2,2,0))))) -> 5 | AV5: 2 | AX5: 0 | AZ5: / | BA5: =IF(OR(AJ3=3,AJ3=4),2,0) -> 0
AN6: 3 | AP6: 0 | AR6: / | AS6: =IF(AJ2>17,6,IF(AJ2>13,5,IF(AJ2>9,4,IF(AJ2>5,3,IF(AJ2>4,2,0))))) -> 5 | AV6: 3 | AX6: 0 | AZ6: / | BA6: =IF(OR(AJ3=5,AJ3=6),2,0) -> 0
AN7: 4 | AP7: 0 | AR7: / | AS7: =IF(AJ2>19,6,IF(AJ2>16,5,IF(AJ2>12,4,IF(AJ2>8,3,IF(AJ2>7,2,IF(AJ2>6,1,0)))))) -> 4 | AV7: 4 | AX7: 0 | AZ7: / | BA7: =IF(OR(AJ3=7,AJ3=8),3,0) -> 0
AN8: 5 | AP8: 0 | AR8: / | AS8: =IF(AJ2>20,6,IF(AJ2>19,5,IF(AJ2>16,4,IF(AJ2>12,3,IF(AJ2>9,2,IF(AJ2>8,1,0)))))) -> 3 | AV8: 5 | AX8: 0 | AZ8: / | BA8: =IF(OR(AJ3=9,AJ3=10,AJ3=11),3,IF(OR(AJ3=12,AJ3=13,AJ3=14,AJ3=15,AJ3=16),4,IF(OR(AJ3=17,AJ3=18,AJ3=19,AJ3=20),5,0))) -> 4
AN9: 6 | AP9: 0 | AR9: / | AS9: =IF(AJ2>20,6,IF(AJ2>19,5,IF(AJ2>18,4,IF(AJ2>14,3,IF(AJ2>11,2,IF(AJ2>10,1,0)))))) -> 2 | AV9: 6 | AX9: 无 | AZ9: / | BA9: =IF(AJ3>10,"玄奥","无") -> 玄奥
AN10: 7 | AP10: 0 | AR10: / | AS10: =IF(AJ2>21,6,IF(AJ2>20,5,IF(AJ2>19,4,IF(AJ2>16,3,IF(AJ2>13,2,IF(AJ2>12,1,0)))))) -> 2 | AV10: 7 | AX10: 无 | AZ10: / | BA10: =IF(AJ3>12,"玄奥","无") -> 玄奥
AN11: 8 | AP11: 0 | AR11: / | AS11: =IF(AJ2>21,5,IF(AJ2>20,4,IF(AJ2>18,3,IF(AJ2>15,2,IF(AJ2>14,1,0))))) -> 0 | AV11: 8 | AX11: 无 | AZ11: / | BA11: =IF(AJ3>14,"玄奥","无") -> 玄奥
AN12: 9 | AP12: 0 | AR12: / | AS12: =IF(AJ2>21,3,IF(AJ2>18,2,IF(AJ2>16,1,0))) -> 0 | AV12: 9 | AX12: 无 | AZ12: / | BA12: =IF(AJ3>16,"玄奥","无") -> 无
AS13: 当前值 | AW13: 最大值
AN14: 术法点 | AV14: / | AZ14: 点

Sheet 战技
A1: 战技
A2: 关联属性 | E2: =主要情况!Q28 -> 力量 | I2: 豁免DC | M2: =主要情况!Y28 -> 5 | S2: 准备战技 | X2: =+IF(E2="力量",主要情况!E5,0)+IF(E2="敏捷",主要情况!E7,0)+IF(E2="体质",主要情况!E9,0)+IF(E2="智力",主要情况!E11,0)+IF(E2="感知",主要情况!E13,0) -> -5 | AA2: 个 | AC2: 流派 | AH2: 摘星流 | AS2: 当前值 | AW2: 最大值
A3: 战技 | E3: 级别 | G3: 战技详述 | AN3: 卓越骰数量 | AV3: / | AZ3: 枚
AN4: 卓越骰大小 | AS4: d4

Sheet 怪物
A1: 怪物资料
A3: 参考怪物资料 | AE3: 最终怪物资料
A4: 将《怪物图鉴》上的怪物初始数据填写在这里 | AE4: 将经过部署强化、购买装备、变形结合等方法修改之后的，部署数据或变形数据，写在这里。
Y6: 部署或变形
Y7: 常驻变形
Y8: 获取方法
Y9: 完全变形术

Sheet 图表
A1: 职业 | B1: 期望生命 | C1: 首级额外生命 | E1: 类人生物 | F1: 巨人 | G1: 精类 | H1: 构装生物 | I1: 不死生物 | J1: 天界生物 | K1: 邪魔 | L1: 植物 | M1: 元素 | N1: 泥怪 | O1: 异怪 | P1: 龙 | Q1: 怪兽 | R1: 野兽 | T1: 属性值 | U1: 花费点数
A2: 狂战士 | B2: 7 | C2: 5 | E2: 定制血统 | F2: 定制血统 | G2: 定制血统 | H2: 定制血统 | I2: 定制血统 | J2: 定制血统 | K2: 定制血统 | L2: 定制血统 | M2: 定制血统 | N2: 定制血统 | O2: 定制血统 | P2: 定制血统 | Q2: 定制血统 | R2: 定制血统 | T2: 8 | U2: 0
A3: 圣武士 | B3: 6 | C3: 4 | E3: 人类 | F3: 歌利亚 | G3: 仙灵 | H3: 机关人 | I3: 剪影 | J3: 阿斯莫 | K3: 提夫林 | L3: 古树 | M3: 元素裔 | N3: 流浆体 | O3: 呋噜 | P3: 狗头人 | Q3: 人马 | T3: 9 | U3: 1
A4: 游侠 | B4: 6 | C4: 4 | E4: 精灵 | F4: 独眼巨人 | G4: 兔人 | H4: 仿生人 | I4: 修罗 | J4: 半梦灵 | K4: 地狱之子 | L4: 蕈人 | M4: 小巨灵 | N4: 生化之雪 | O4: 眼魔 | P4: 真龙 | Q4: 原体蛇人 | T4: 10 | U4: 2
A5: 武僧 | B5: 5 | C5: 3 | E5: 矮人 | G5: 半羊人 | H5: 稻草人 | I5: 血族 | J5: 福瑞天族 | K5: 欲魔 | L5: 阿娜温 | O5: 厄兰 | Q5: 牛头人 | T5: 11 | U5: 3
A6: 灵能武士 | B6: 6 | C6: 4 | E6: 侏儒 | G6: 天狗 | H6: 自动侏儒 | I6: 重生者 | Q6: 狮人 | T6: 12 | U6: 4
A7: 游荡者 | B7: 5 | C7: 3 | E7: 半身人 | G7: 幻身灵 | Q7: 螳螂人 | T7: 13 | U7: 5
A8: 奇械师 | B8: 5 | C8: 3 | E8: 兽人 | G8: 狐妖 | Q8: 象人 | T8: 14 | U8: 7
A9: 契术师 | B9: 5 | C9: 3 | E9: 化兽者 | G9: 巫咒之子 | Q9: 鼯猴人 | T9: 15 | U9: 9
A10: 吟游诗人 | B10: 5 | C10: 3 | E10: 吉斯人 | T10: 16 | U10: 12
A11: 牧师 | B11: 5 | C11: 3 | E11: 地精
A12: 德鲁伊 | B12: 5 | C12: 3 | E12: 猫人
A13: 灵能师 | B13: 4 | C13: 2 | E13: 维多肯
A14: 法师 | B14: 4 | C14: 2 | E14: 蜥蜴人
E15: 龟人
A16: 初始职业生命值 | B16: =IFERROR(VLOOKUP(主要情况!M7,A2:C14,2,0)*主要情况!W7+VLOOKUP(主要情况!M7,A2:C14,3,0),0) -> 0 | E16: 鹰人
A17: 兼职一生命值 | B17: =IFERROR(VLOOKUP(主要情况!M8,A2:C14,2,0)*主要情况!W8,0) -> 0 | E17: 鱼人
A18: 兼职二生命值 | B18: =IFERROR(VLOOKUP(主要情况!M9,A2:C14,2,0)*主要情况!W9,0) -> 0
A19: 兼职三生命值 | B19: =IFERROR(VLOOKUP(主要情况!M10,A2:C14,2,0)*主要情况!W10,0) -> 0
A21: 总生命值 | B21: =SUM(B16:B19)+主要情况!E9*主要情况!M4 -> 0
A23: 狂战士子职业 | B23: 圣武士子职业 | C23: 游侠子职业 | D23: 武僧子职业 | E23: 灵能武士子职业 | F23: 游荡者子职业 | G23: 奇械师子职业 | H23: 契术师子职业 | I23: 吟游诗人子职业 | J23: 牧师子职业 | K23: 德鲁伊子职业 | L23: 灵能师子职业 | M23: 法师子职业
A24: 图腾武者 | B24: 奉献之誓 | C24: 狩魔猎人 | D24: 散打宗 | E24: 风物行者 | F24: 刺客 | G24: 构造铁匠 | H24: 邪魔 | I24: 轶闻学院 | J24: 生命领域 | K24: 大地结社 | L24: 创形修会 | M24: 防护学派
A25: 先祖守卫 | B25: 古贤之誓 | C25: 魔射手 | D25: 暗影宗 | E25: 回音骑士 | F25: 斥候 | G25: 魔炮专家 | H25: 至高妖精 | I25: 偶像学院 | J25: 死亡领域 | K25: 月亮结社 | L25: 惑心修会 | M25: 变化学派
A26: 狂热者 | B26: 复仇之誓 | C26: 兽王 | D26: 四象宗 | E26: 守卫铁卫 | F26: 诡术师 | G26: 装甲师 | H26: 旧日支配者 | I26: 勇气学院 | J26: 和平领域 | K26: 星辰结社 | L26: 旅行修会 | M26: 咒法学派
A27: 巨人 | B27: 救赎之誓 | C27: 龙兽守卫 | D27: 日魂宗 | E27: 原力大师 | F27: 策士 | G27: 炼金师 | H27: 咒剑 | I27: 剑舞学院 | J27: 战争领域 | K27: 牧人结社 | L27: 洞察修会 | M27: 幻术学派
A28: 自然先驱 | B28: 守望之誓 | C28: 士官长 | D28: 命流宗 | E28: 魂刃主宰 | F28: 鬼魅 | G28: 神枪手 | H28: 死灵 | I28: 低语学院 | J28: 光明领域 | K28: 孢子结社 | L28: 百变修会 | M28: 死灵学派
A29: 狂野魔法 | B29: 荣耀之誓 | C29: 边界行者 | D29: 剑圣宗 | F29: 游荡剑客 | G29: 机车士 | H29: 巨灵 | I29: 创造学院 | J29: 幽暗领域 | K29: 梦境结社 | L29: 能量修会 | M29: 预言学派
A30: 野兽 | B30: 王冠之誓 | C30: 幽域追踪者 | D30: 星我宗 | F30: 役虫者 | G30: 科学怪人 | H30: 深海意志 | I30: 灵魂学院 | J30: 律法领域 | K30: 野火结社 | M30: 附魔学派
A31: 鲜血 | B31: 破晓之誓 | C31: 妖精漫游者 | D31: 神龙宗 | F31: 自由之翼 | H31: 灵契师 | J31: 狂野领域 | K31: 风暴结社 | M31: 塑能学派
B32: 飨食之誓 | C32: 海洋保护者 | D32: 酒仙宗 | J32: 奥秘领域 | K32: 凛冬结社 | M32: 书士会
B33: 月剑之誓 | C33: 剧毒杀手 | J33: 心灵领域 | K33: 牧位者 | M33: 符咒女巫
B34: 玫瑰之誓 | J34: 剑舞领域 | M34: 幽影魔法
J35: 时间领域 | M35: 时间魔法
M36: 重力魔法
A38: 专长名称 | B38: 专长效果
A39: 雾隐之力 | B39: 迷雾隐藏了你的人物的一部分记忆。随着时间流逝，越来越多的遗失记忆回到了你身上，这也许会在特定的时候帮助你。 该专长没有帮助角色扮演之外的效果。然而，在游戏进行的任何时段，你可以在长休完成后，把这个专长转变成另一个你能选取的、并且符合你人物背景的专长。这表现为你在睡梦中恢复了经验技术。 雾隐之力本身也需要遵守“一个专长只能选择一次”的规则限制。你不能在把雾隐之力转化为其它专长后，再次选择雾隐之力作为专长。
A40: 专精专注 | B40: 你非常擅长保持专注，获得以下好处： ·你在专注豁免上可以加上熟练加值。如果原本已经可以加上熟练加值，改为加上双倍的熟练加值。 ·当你因陷入失能而即将中断专注时，你可以令专注暂时不因失能而中断。在你的下个回合结束后，如果你依然处于失能状态，则专注中断。
A41: 威力攻击 | B41: 发动一次攻击检定之前，你可以让该次攻击检定承受-5减值。若命中，该次攻击的伤害掷骰获得等同于其基础伤害骰最大值的加值。举例来说，巨剑和灼热射线（2d6）额外造成12点伤害，长弓和11级武僧的徒手打击（1d8）额外造成8点伤害，魔能爆（1d10）额外造成10点伤害，长柄武器大师的附赠攻击和匕首（1d4）额外造成4点伤害。 焰舌、神圣武器、脆弱诅咒、精通至圣斩、超魔、战技、重击、偷袭等可能产生额外伤害骰的各种效果，都对威力攻击没有影响。
A42: 战士 | B42: 你接受了一定程度的军事训练，这给你带来以下好处： ·你获得一项军用武器熟练。 ·你从任意职业中选择并习得一项战斗风格。
A43: 巫师 | B43: 你接受了一定程度的魔法训练，这给你带来以下好处： ·你从“魔法伎俩”“奇术”“德鲁伊伎俩”“念合”中选择并习得一种戏法。 ·你从任意职业中选择并习得一种法术风格。
...

Sheet 计算器
A1: 购点计算器 | F1: 属性提升 | M1: 物品素材计算器
B2: 属性值 | C2: 调整值 | D2: 花费点数 | G2: 购点/骰点值 | H2: 升级 | I2: 专长 | J2: 物品 | K2: 最终结果 | M2: 物品种类 | N2: 价格（gp） | O2: 无机素材（份） | P2: 有机素材（份） | Q2: 魔晶（份） | R2: 工艺费用（gp）
A3: 力量 | B3: 10 | C3: =INT(B3/2-5) -> 0 | D3: =VLOOKUP(B3,图表!T1:U10,2,FALSE) -> 2 | F3: 力量 | G3: =B3 -> 10 | K3: =SUM(G3:J3) -> 10 | M3: 服饰（手套、护腿、斗篷、外套、帽子、鞋子） | N3: 1000 | O3: =VLOOKUP(M3,图表!K86:N97,2,0)*N3/100 -> 20 | P3: =VLOOKUP(M3,图表!K86:N97,3,0)*N3/100 -> 40 | Q3: =VLOOKUP(M3,图表!K86:N97,4,0)*N3/100 -> 20 | R3: =N3*0.2 -> 200
A4: 敏捷 | B4: 15 | C4: =INT(B4/2-5) -> 2 | D4: =VLOOKUP(B4,图表!T1:U10,2,FALSE) -> 9 | F4: 敏捷 | G4: =B4 -> 15 | K4: =SUM(G4:J4) -> 15
A5: 体质 | B5: 15 | C5: =INT(B5/2-5) -> 2 | D5: =VLOOKUP(B5,图表!T1:U10,2,FALSE) -> 9 | F5: 体质 | G5: =B5 -> 15 | K5: =SUM(G5:J5) -> 15
A6: 智力 | B6: 10 | C6: =INT(B6/2-5) -> 0 | D6: =VLOOKUP(B6,图表!T1:U10,2,FALSE) -> 2 | F6: 智力 | G6: =B6 -> 10 | K6: =SUM(G6:J6) -> 10
A7: 感知 | B7: 15 | C7: =INT(B7/2-5) -> 2 | D7: =VLOOKUP(B7,图表!T1:U10,2,FALSE) -> 9 | F7: 感知 | G7: =B7 -> 15 | K7: =SUM(G7:J7) -> 15
M8: 怪物素材计算器
A9: 总和 | B9: =SUM(B3:B7) -> 65 | C9: =SUM(C3:C7) -> 6 | D9: =SUM(D3:D7) -> 31 | M9: 生物类型 | N9: 怪物等级 | O9: 怪物数量 | P9: 无机素材 | Q9: 有机素材 | R9: 魔晶
A10: 购点选项 | B10: 32 | C10: 购点法 | M10: 构装生物 | N10: 20 | O10: 1 | P10: =VLOOKUP(M10,图表!Q86:T100,2,0)*N10*N10*O10 -> 480 | Q10: =VLOOKUP(M10,图表!Q86:T100,3,0)*N10*N10*O10 -> 0 | R10: =VLOOKUP(M10,图表!Q86:T100,4,0)*N10*N10*O10 -> 120
A11: 剩余点数 | B11: =B10-D9 -> 1 | C11: 点 | F11: d20成功率计算器
G12: 优劣情况 | H12: 加值 | I12: 目标值 | J12: 达到目标的概率
F13: D20 | G13: 均势 | H13: 9 | I13: 20 | J13: =IF(G13="均势",G16,IF(G13="一重优势",1-G15*G15,IF(G13="两重优势",1-G15*G15*G15,IF(G13="一重劣势",G16*G16,IF(G13="两重劣势",G16*G16*G16,IF(G13="三重优势",1-G15*G15*G15*G15,G16*G16*G16*G16)))))) -> 0.5
F15: 均势失败率 | G15: =MAX(-0.05+(I13-H13)/20,0) -> 0.5 | M15: 伤害计算器
F16: 均势成功率 | G16: =MIN(1.05-(I13-H13)/20,1) -> 0.5 | N16: 骰子总数 | O16: 骰子面数
M17: 骰值伤害1 | N17: 2 | O17: d6 | Q17: 伤害期望（常规）
F18: 攻击命中率计算器 | M18: 骰值伤害2 | N18: 4 | O18: d4 | Q18: =N21+N17*VLOOKUP(O17,图表!K46:L50,2,0)+N18*VLOOKUP(O18,图表!K46:L50,2,0)+N19*VLOOKUP(O19,图表!K46:L50,2,0)+N20*VLOOKUP(O20,图表!K46:L50,2,0) -> 27
G19: 优劣情况 | H19: 加值 | I19: 目标AC | J19: 命中目标的概率 | M19: 骰值伤害3 | O19: d8 | Q19: 伤害期望（重击）
F20: D20 | G20: 一重优势 | H20: 3 | I20: 20 | J20: =IF(G20="均势",G23,IF(G20="一重优势",1-G22*G22,IF(G20="两重优势",1-G22*G22*G22,IF(G20="一重劣势",G23*G23,IF(G20="两重劣势",G23*G23*G23,IF(G20="三重优势",1-G22*G22*G22*G22,G23*G23*G23*G23)))))) -> 0.36 | M20: 骰值伤害4 | O20: d12 | Q20: =N21+2*N17*VLOOKUP(O17,图表!K46:L50,2,0)+2*N18*VLOOKUP(O18,图表!K46:L50,2,0)+2*N19*VLOOKUP(O19,图表!K46:L50,2,0)+2*N20*VLOOKUP(O20,图表!K46:L50,2,0) -> 44
F21: 重击范围 | G21: 2 | J21: 重击的概率 | M21: 固定值伤害 | N21: 10
F22: 均势失败率 | G22: =1-G23 -> 0.8 | J22: =IF(G20="均势",0.05*G21,IF(G20="一重优势",1-(1-0.05*G21)*(1-0.05*G21),IF(G20="两重优势",1-(1-0.05*G21)*(1-0.05*G21)*(1-0.05*G21),IF(G20="三重优势",1-(1-0.05*G21)*(1-0.05*G21)*(1-0.05*G21)*(1-0.05*G21),IF(G20="一重劣势",(0.05*G21)*(0.05*G21),IF(G20="两重劣势",(0.05*G21)*(0.05*G21)*(0.05*G21),(0.05*G21)*(0.05*G21)*(0.05*G21)*(0.05*G21))))))) -> 0.19
F23: 均势成功率 | G23: =MIN(MAX(MIN(1.05-(I20-H20)/20,1),G21*0.05),0.95) -> 0.2 | M23: 结合使用“攻击命中率计算器”和“伤害计算器”
M24: 计算命中率、重击率之后的单次攻击伤害期望 | P24: =Q18*(J20-J22)+Q20*J22 -> 12.95
